## 代码输出 - 41

```js
let x, y;
try {
  throw new Error();
} catch (x) {
  x = 1;
  y = 2;
  console.log(x);
}
console.log(x);
console.log(y);
```

::: details 答案

```txt
1
undefined
2
```

需要注意的是 catch 的作用域，其实并不是常见的块作用域，并不能绑定自己的内部声明的变量。catch 创建的块作用域，只对 catch
的参数有效。对于在内部声明的变量，catch 并没有创建一个新的作用域，只是一个普通的代码块。
:::
